I'm sorry, but an uncaught exception occurred.

While running game code:
  File "game/mys1.rpy", line 310, in script
    if player_clues["key_to_upper_deck"] == TRUE:
  File "game/mys1.rpy", line 310, in <module>
    if player_clues["key_to_upper_deck"] == TRUE:
NameError: name 'TRUE' is not defined

-- Full Traceback ------------------------------------------------------------

Full traceback:
  File "game/mys1.rpy", line 310, in script
    if player_clues["key_to_upper_deck"] == TRUE:
  File "/Users/kiramki/Downloads/renpy/renpy/ast.py", line 1849, in execute
    if renpy.python.py_eval(condition):
  File "/Users/kiramki/Downloads/renpy/renpy/python.py", line 1209, in py_eval
    return py_eval_bytecode(code, globals, locals)
  File "/Users/kiramki/Downloads/renpy/renpy/python.py", line 1202, in py_eval_bytecode
    return eval(bytecode, globals, locals)
  File "game/mys1.rpy", line 310, in <module>
    if player_clues["key_to_upper_deck"] == TRUE:
NameError: name 'TRUE' is not defined

macOS-15.2-arm64-arm-64bit arm64
Ren'Py 8.3.4.24120703
frostbound 1.0
Tue Dec 31 20:38:38 2024
